[2025-10-08T23:46:28.249+0000] {local_task_job_runner.py:120} INFO - ::group::Pre task execution logs
[2025-10-08T23:46:28.281+0000] {taskinstance.py:2076} INFO - Dependencies all met for dep_context=non-requeueable deps ti=<TaskInstance: orchestrator_bronze_silver_refined.upload_to_bronze manual__2025-10-08T23:46:27+00:00 [queued]>
[2025-10-08T23:46:28.288+0000] {taskinstance.py:2076} INFO - Dependencies all met for dep_context=requeueable deps ti=<TaskInstance: orchestrator_bronze_silver_refined.upload_to_bronze manual__2025-10-08T23:46:27+00:00 [queued]>
[2025-10-08T23:46:28.288+0000] {taskinstance.py:2306} INFO - Starting attempt 1 of 1
[2025-10-08T23:46:28.301+0000] {taskinstance.py:2330} INFO - Executing <Task(PythonOperator): upload_to_bronze> on 2025-10-08 23:46:27+00:00
[2025-10-08T23:46:28.313+0000] {standard_task_runner.py:64} INFO - Started process 618 to run task
[2025-10-08T23:46:28.317+0000] {standard_task_runner.py:90} INFO - Running: ['***', 'tasks', 'run', 'orchestrator_bronze_silver_refined', 'upload_to_bronze', 'manual__2025-10-08T23:46:27+00:00', '--job-id', '51', '--raw', '--subdir', 'DAGS_FOLDER/dag_orchestrator_pipeline.py', '--cfg-path', '/tmp/tmp_m2auopz']
[2025-10-08T23:46:28.319+0000] {standard_task_runner.py:91} INFO - Job 51: Subtask upload_to_bronze
[2025-10-08T23:46:28.393+0000] {task_command.py:426} INFO - Running <TaskInstance: orchestrator_bronze_silver_refined.upload_to_bronze manual__2025-10-08T23:46:27+00:00 [running]> on host 651334a32e37
[2025-10-08T23:46:28.485+0000] {taskinstance.py:2648} INFO - Exporting env vars: AIRFLOW_CTX_DAG_OWNER='Fia' AIRFLOW_CTX_DAG_ID='orchestrator_bronze_silver_refined' AIRFLOW_CTX_TASK_ID='upload_to_bronze' AIRFLOW_CTX_EXECUTION_DATE='2025-10-08T23:46:27+00:00' AIRFLOW_CTX_TRY_NUMBER='1' AIRFLOW_CTX_DAG_RUN_ID='manual__2025-10-08T23:46:27+00:00'
[2025-10-08T23:46:28.486+0000] {taskinstance.py:430} INFO - ::endgroup::
[2025-10-08T23:46:29.194+0000] {taskinstance.py:441} INFO - ::group::Post task execution logs
[2025-10-08T23:46:29.195+0000] {taskinstance.py:2905} ERROR - Task failed with exception
Traceback (most recent call last):
  File "/opt/airflow/utils/pipeline_utils.py", line 33, in upload_file_to_minio
    client.head_bucket(Bucket=bucket)
  File "/home/airflow/.local/lib/python3.11/site-packages/botocore/client.py", line 569, in _api_call
    return self._make_api_call(operation_name, kwargs)
           ^^^^^^^^^^^^^^^^^^^^^^^^^^^^^^^^^^^^^^^^^^^
  File "/home/airflow/.local/lib/python3.11/site-packages/botocore/client.py", line 1023, in _make_api_call
    raise error_class(parsed_response, operation_name)
botocore.exceptions.ClientError: An error occurred (403) when calling the HeadBucket operation: Forbidden

During handling of the above exception, another exception occurred:

Traceback (most recent call last):
  File "/home/airflow/.local/lib/python3.11/site-packages/airflow/models/taskinstance.py", line 465, in _execute_task
    result = _execute_callable(context=context, **execute_callable_kwargs)
             ^^^^^^^^^^^^^^^^^^^^^^^^^^^^^^^^^^^^^^^^^^^^^^^^^^^^^^^^^^^^^
  File "/home/airflow/.local/lib/python3.11/site-packages/airflow/models/taskinstance.py", line 432, in _execute_callable
    return execute_callable(context=context, **execute_callable_kwargs)
           ^^^^^^^^^^^^^^^^^^^^^^^^^^^^^^^^^^^^^^^^^^^^^^^^^^^^^^^^^^^^
  File "/home/airflow/.local/lib/python3.11/site-packages/airflow/models/baseoperator.py", line 401, in wrapper
    return func(self, *args, **kwargs)
           ^^^^^^^^^^^^^^^^^^^^^^^^^^^
  File "/home/airflow/.local/lib/python3.11/site-packages/airflow/operators/python.py", line 235, in execute
    return_value = self.execute_callable()
                   ^^^^^^^^^^^^^^^^^^^^^^^
  File "/home/airflow/.local/lib/python3.11/site-packages/airflow/operators/python.py", line 252, in execute_callable
    return self.python_callable(*self.op_args, **self.op_kwargs)
           ^^^^^^^^^^^^^^^^^^^^^^^^^^^^^^^^^^^^^^^^^^^^^^^^^^^^^
  File "/opt/airflow/dags/dag_orchestrator_pipeline.py", line 39, in upload_to_bronze
    upload_file_to_minio(LOCAL_CSV, bucket='bronze', key=key)
  File "/opt/airflow/utils/pipeline_utils.py", line 35, in upload_file_to_minio
    client.create_bucket(Bucket=bucket)
  File "/home/airflow/.local/lib/python3.11/site-packages/botocore/client.py", line 569, in _api_call
    return self._make_api_call(operation_name, kwargs)
           ^^^^^^^^^^^^^^^^^^^^^^^^^^^^^^^^^^^^^^^^^^^
  File "/home/airflow/.local/lib/python3.11/site-packages/botocore/client.py", line 1023, in _make_api_call
    raise error_class(parsed_response, operation_name)
botocore.exceptions.ClientError: An error occurred (InvalidAccessKeyId) when calling the CreateBucket operation: The Access Key Id you provided does not exist in our records.
[2025-10-08T23:46:29.203+0000] {taskinstance.py:1206} INFO - Marking task as FAILED. dag_id=orchestrator_bronze_silver_refined, task_id=upload_to_bronze, run_id=manual__2025-10-08T23:46:27+00:00, execution_date=20251008T234627, start_date=20251008T234628, end_date=20251008T234629
[2025-10-08T23:46:29.211+0000] {standard_task_runner.py:110} ERROR - Failed to execute job 51 for task upload_to_bronze (An error occurred (InvalidAccessKeyId) when calling the CreateBucket operation: The Access Key Id you provided does not exist in our records.; 618)
[2025-10-08T23:46:29.253+0000] {local_task_job_runner.py:243} INFO - Task exited with return code 1
[2025-10-08T23:46:29.269+0000] {taskinstance.py:3503} INFO - 0 downstream tasks scheduled from follow-on schedule check
[2025-10-08T23:46:29.272+0000] {local_task_job_runner.py:222} INFO - ::endgroup::
